{"uuid": "d46402c1-bbc4-4308-8801-b2fed511b7a5", "children": ["4ad4514e-a9f3-4662-9870-0f872d71b79b", "785b84a8-6f17-4e27-8da1-d045897ad131"], "befores": [{"name": "test_setup", "status": "broken", "statusDetails": {"message": "selenium.common.exceptions.WebDriverException: Message: 'chromedriver.exe' executable needs to be in PATH. Please see https://sites.google.com/a/chromium.org/chromedriver/home\n\n", "trace": "  File \"c:\\users\\hareesh\\appdata\\local\\programs\\python\\python37-32\\lib\\site-packages\\pluggy\\callers.py\", line 187, in _multicall\n    res = hook_impl.function(*args)\n  File \"c:\\users\\hareesh\\appdata\\local\\programs\\python\\python37-32\\lib\\site-packages\\_pytest\\fixtures.py\", line 923, in pytest_fixture_setup\n    result = call_fixture_func(fixturefunc, request, kwargs)\n  File \"c:\\users\\hareesh\\appdata\\local\\programs\\python\\python37-32\\lib\\site-packages\\_pytest\\fixtures.py\", line 778, in call_fixture_func\n    res = next(it)\n  File \"C:\\Users\\Hareesh\\PycharmProjects\\Automation_POM_6\\conftest.py\", line 16, in test_setup\n    driver = webdriver.Chrome(executable_path=cur_dir + \"/drivers/chromedriver.exe\")\n  File \"c:\\users\\hareesh\\appdata\\local\\programs\\python\\python37-32\\lib\\site-packages\\selenium\\webdriver\\chrome\\webdriver.py\", line 73, in __init__\n    self.service.start()\n  File \"c:\\users\\hareesh\\appdata\\local\\programs\\python\\python37-32\\lib\\site-packages\\selenium\\webdriver\\common\\service.py\", line 83, in start\n    os.path.basename(self.path), self.start_error_message)\n"}, "start": 1554935001205, "stop": 1554935001377}], "start": 1554935001205, "stop": 1554935001580}